package com.mystudy.ex01_exception;

public class ExceptionFinally {
	 
	public static void main(String[] args) {
		// try ~ catch ~ finally
		System.out.println("---- main() 시작 -----");
		int num = 20;
		int result = 0;
		try {
			System.out.println(">> try문 시작 ");
			num = 30;
			result = 100 / num;
		    System.out.println(">> 연산처리 정상 종료 ");
			System.out.println(">> try문 종료 ");
//			return;
		} catch(ArithmeticException e) {
			System.out.println(">>>> catch 문 실행 ");
		} finally { // return; 문장이 있어도 무조건 실행 
			System.out.println("***> finally : 항상실행 (무조건)");
		}
	    
		
		System.out.println("---------------------------");
	    	
		System.out.println("----- main() 종료 -----");
		
	}
	
	static String test() {
		String result = "";
		int[] num = new int[3]; //인덱스 0, 1, 2
		try {
			num[3] = 100;
			result = "<정상실행>";
		}catch (Exception e){
			result = "<예외발생>" + e.getMessage();
		}finally {
			System.out.println("==== finally ========");
		}
		
		
		return result;
	}
	

}
