package com.mystudy.ex01_exception;

public class ExceptionEx {

	public static void main(String[] args) {
		System.out.println("----  main() 시작 ----");
		int num = 100;
		int num1 = 10;
		int num2 = 30;
		int result = 0;
		System.out.println(">> 연산시작");
	    // result = num / num1;
		// 예외처리 ---------------------------
		if(num1 == 0) {
			System.out.println("[예외발생] 나누는 값이 0입니다.");
		}else {
			result = num/num1;
		}
	    System.out.println("result : "+result);
		// -----------------------------------------
	    // 예외처리 : try ~ catch 문으로 예외 처리 
	    System.out.println("--- try ~ catch 문 처리 ---");
	    try {
	    	result = num/num1;
	    	System.out.println("result : "+result); // 여기서 문제면 catch에서 거름
	    } catch(ArithmeticException ex) { // 비정상시 여기에서 코드 실행 
	    	System.out.println("[예외발생-메시지]"+ex.getMessage());
            ex.printStackTrace();
	    } 
	    
	    
		System.out.println("----  main() 종료 ----");
	    
		
	    
	}
}
